Workbook

Sheet DV (3 copies)
A1: DISBURSEMENT VOUCHER
V3: Fund Cluster : | AB3: STO-REG-ALMED
V4: Date :
V5: DV No. :
A6: Mode of Payment
H7: MDS Check | M7: Commercial Check | T7: ADA | X7: Others (Please specify)
AA8: _________________
A9: Payee | E9: ='Itinerary (3 copies)'!D17 -> WARREN A. DEL ROSARIO | S9: TIN/Employee No.: | AB9: ORS/BURS No.:
S10: 389-477-383-000 / 318
A11: Address | E11: SRDC Building, Elliptical Road corner Visayas Ave, Diliman Quezon City
A12: Particulars | R12: Responsibility Center | W12: MFO/PAP | AB12: Amount
A13: To reimburse allowable per diem and transporation cost as per attached supporting documents in the amount of ......
R14: =IFERROR(VLOOKUP($AB$3,'Fund Source'!$B:$D,2,FALSE),"") -> 15-03-01-03 | W14: =IFERROR(VLOOKUP($AB$3,'Fund Source'!$B:$D,3,FALSE),"") -> 200000-10000-1000 | AB14: ='Itinerary (3 copies)'!I13 -> 8116
W15: =AB3 -> STO-REG-ALMED
B17: T.O. #: 2026-07-11246
B18: Date: July 15, 2026
B19: Destination:Sta Maria, Laguna, Region IV-A and Points
A20: Amount Due | AB20: =SUM(AB13:AF19) -> 8116
A21: A. | B21: Certified: Expenses/Cash Advance necessary, lawful and incurred under my direct supervision.
B23: ENGR. ANGELICA L. ECITO
L24: Supervising Agriculturist
A25: B. | B25: Accounting Entry:
A26: Account Title | S26: UACS Code | X26: Debit | AC26: Credit
B27: Traveling Expenses - Local | T27: 5-02-01-01 0
C28: Cash-Modified Disbursement System (MDS), Regular | S28: 1-01-04-04 0-01
A29: C. | B29: Certified: | S29: D. Approved for Payment | T29: Approved for Payment
C30: Cash available
C32: Subject to Authority to Debit Account (when applicable)
C34: Supporting documents complete and amount claimed | D34: Supporting documents complete and amount claimed
C35: proper
A36: Signature | S36: Signature
A38: Printed Name | E38: RODRIGO I. ABLAZA | S38: Printed Name | W38: JOVETTE T. ALMEDA
A40: Position | E40: Head, Accounting Unit | S40: Position | W40: Chief, ALMED
A42: Date | S42: Date
A44: E. | B44: Receipt of Payment | AB44: JEV No.
A45: Check/ ADA No. : | N45: Date : | S45: Bank Name & Account Number:
A47: Signature: | N47: Date : | S47: Printed Name: | AB47: Date
A49: Official Receipt No. & Date/Other Documents

Sheet likod ng DV
B1: Republic of the Philippines
B2: DEPARTMENT OF AGRICULTURE
B3: BUREAU OF SOILS AND WATER MANAGEMENT
B4: SRDC Building Elliptical Road corner Visayas Avenue, Diliman, Quezon City 1101
A6: MANDATORY MINIMUM SUPPORTING DOCUMENTS FOR COMMON TRANSACTION
A7: Updated per Circular no. 2023-004 dated as of June 14, 2023
A8: *To be filled only by the Processing Officer*
A9: --- TRAVELLING EXPENSES ---
A11: Payee : | B11: ='DV (3 copies)'!E9 -> WARREN A. DEL ROSARIO | D11: Date:
A12: Amount: | B12: ='DV (3 copies)'!AB20 -> 8116
A13: Fund Source: | B13: ='DV (3 copies)'!AB3 -> STO-REG-ALMED
A15: Page # | B15: SUPPORTING DOCUMENTS | D15: REMARKS
B17: Disbursement Voucher- 3 copies
B18: Obligation Request - 3 copies
B19: Itinerary of Travel - 2 copies
B20: Travel Order (duly approved by the Director)
B21: Evidence of travel completed
C22: Plane ticket
C23: Bus / boat ticket
C24: Taxi (P500.00) / Grab (300.00) ticket
C25: Boarding pass
C26: Terminal Fee Ticket
C27: Trip Ticket
C28: Official receipt from travel
C29: Reimbursement expense receipt (RER) (P300.00 - 1,000.00)
C30: Certificate not requiring reciept (COA Cir. 2017-001) (up to P300.00)
B31: Original Certificate of Appearance/ Attendance
B32: Certificate of Travel Completed
B33: Accomplishment Report with documentation (pictures with date)
B34: Memorandum signed by the the Director, if any
B36: Additional Requirements for non-BSWM employees:
B37: Memorandum / Invitation letter for National seminars,trainings and workshops.
B38: Approved travel order from their originated agency signed by Director
B39: Certificate of No claims signed by their Accountant
A42: Note : | B42: Attach all the documents in order per checklist.
B43: Erasures must be countersigned by proper authority.
B44: For claims of more than one travel in one voucher, please arrange the documents per Travel Order. ( for other group participants)
B45: Reimbursement - Deadline of submission will be submitted within 30 CD upon return from his travel to his permanent station.
B46: Liquidation - 30 CD for local travel after return to the official station, 60 CD for foreign travel
B47: It should be stated in the Itinerary of Travel the claimant's Official Station Address for accounting review purposes.
...

Sheet ORS (4copies)
L1: Appendix 11 | P1: To download this form, click "File", "Download", and "Microsoft Excel"
A3: OBLIGATION REQUEST AND STATUS | K3: Serial No. : 02-01101101-2026-03
A4: BUREAU OF SOILS AND WATER MANAGEMENT | K4: Date : _________________________
A5: Entity Name | K5: Fund Cluster : 01 | P5: REMINDERS:
A6: Payee | D6: ='Itinerary (3 copies)'!D17 -> WARREN A. DEL ROSARIO | O6: 1 | P6: Print four (4) copies of ORS
O7: 2 | P7: Print the ORS checklist at the back of the 1st copy of ORS.
A8: Office | D8: BUREAU OF SOILS AND WATER MANAGEMENT | O8: 3 | P8: Green font - fill out correct details (Payee, Office, Address, T.O.#, Date of Travel, Destination & Signatory for Box A)
O9: 4 | P9: Violet font - indicate the correct RC & MFO/PAP
A10: Address | D10: SRDC Building, Elliptical Road corner Visayas Ave, Diliman Quezon City | Q10: SAMPLE RC | R10: Please check BSWM - 2023 RC & MFO/PAP
P11: RC Code: | Q11: 15-03-01-03
A12: Responsibility Center | D12: Particulars | I12: MFO/PAP | K12: UACS Object Code | L12: Amount | P12: Fund Source: | Q12: STO-REG
P13: Division/Center: | Q13: ALMED
A14: ='DV (3 copies)'!R14 -> 15-03-01-03 | D14: To reimburse actual travelling expenses and allowable per diem as per attached supporting documents in the amount of ...... | I14: ='DV (3 copies)'!W14 -> 200000-10000-1000 | K14: 50201010-00 | P14: RC Code: | R14: <-c/o Budget Section
A15: ='DV (3 copies)'!W15 -> STO-REG-ALMED | L15: ='Itinerary (3 copies)'!I13 -> 8116 | P15: Fund Source: | Q15: REGULAR
D17: ='DV (3 copies)'!B17 -> T.O. #: 2026-07-11246
D18: ='DV (3 copies)'!B18 -> Date: July 15, 2026
D19: ='DV (3 copies)'!B19 -> Destination:Sta Maria, Laguna, Region IV-A and Points
P21: 50299990-99 (for TEV of COS)
D22: Total | L22: =SUM(L14:M21) -> 8116 | P22: **make sure that the status of appointment indicated in the travel order is correct (Permanent or Contract of Service)
A23: A. | D23: Charges to appropriation/alloment are | I23: B.
B24: Certified: | J24: Certified: Allotment available and obligated
B25: necessary, lawful and under my direct supervision;and | J25: for the purpose/adjustment necessary as
B26: supporting documents valid, proper and legal | J26: indicated above
A31: Signature : ___________________________________ | I31: Signature : ___________________________________
A33: Printed Name : JOVETTE T. ALMEDA | I33: Printed Name : SARAH B. SUMINISTRADO
A35: Position : Chief, ALMED | I35: Position : Head, Budget Section
A37: Date : ____________________________________ | I37: Date : ____________________________________
A40: C. | B40: STATUS OF OBLIGATION
A41: Reference | H41: Amount
A42: Date | B42: Particulars | E42: ORS/JEV/Check/ ADA/TRA No. | H42: Obligation | I42: Payable | K42: Payment | L42: Balance
L43: Not Yet Due | M43: Due and Demandable
H44: (a) | I44: (b) | K44: (c) | L44: (a-b) | M44: (b-c)
B46: Obligation | H46: =L22 -> 8116

Sheet Itinerary (3 copies)
A1: ITINERARY OF TRAVEL
A2: Name: | B2: WARREN A. DEL ROSARIO | D2: Date of Travel : July 6-10, 2026
A3: Position: | B3: Agriculturist II | D3: Purpose of Travel : To conduct land suitability evaluation of the proposed site
A4: Official Station : SRDC Bldg. Elliptical Road Corner Visayas Avenue Diliman, Quezon City
A6: Date (2026) July | B6: Places to be visited | C6: T I M E | E6: Means of | F6: Transporstation Cost | G6: Per | H6: Others | I6: Total Amount
B7: (Destination) | C7: Departure | D7: Arrival | E7: Transportation | G7: Diem
A8: July 21, 2026 | B8: From Residence to Pick up Points Philcoa, Quezon City | C8: 7:44 AM | D8: 8:25 AM | E8: Indrive | F8: 219 | G8: 2200 | H8: 0 | I8: =F8+G8+H8 -> 2419
B9: To Espiritu Farm, Sta Maria, Laguna | D9: 10:30 AM | E9: Private | G9: 0 | H9: 0 | I9: =F9+G9+H9 -> 0
A10: July 22-23, 2026 | B10: At Espiritu Farm, Sta Maria, Laguna | C10: 7:30 AM | D10: 6:30 PM | E10: Private | F10: 0 | G10: 4400 | H10: 0 | I10: =F10+G10+H10 -> 4400
A11: July 24, 2026 | B11: From Espiritu Farm to BSWM Quezon City | C11: 11:30 AM | D11: 4:00 PM | E11: Private | F11: 0 | G11: 1100 | H11: 0 | I11: =F11+G11+H11 -> 1100
B12: To Permanent Residence | C12: 4:30 AM | D12: 5:11 PM | E12: Indrive | F12: 197 | H12: 0 | I12: =F12+G12+H12 -> 197
A13: TOTAL | F13: =SUM(F8:F12) -> 416 | G13: =SUM(G8:G12) -> 7700 | H13: =SUM(H8:H12) -> 0 | I13: =SUM(I8:I12) -> 8116
D14: Prepared by :
A17: I certify that : (1) I have reviewed the foregoing itinerary, (2) the travel is necessary to the service, (3) the period covered is reasonable and (4) the expenses claimed are proper. | D17: WARREN A. DEL ROSARIO
D18: Agriculturist II
D19: Approved by:
A23: REGINE MARIE B. SABORNIDO | D23: JOVETTE T. ALMEDA
A24: Senior Agriculturist | D24: Chief, ALMED

Sheet Certificate not Require Receipt
A1: Pursuant to COA Circular No. 2017-001 dated June 19, 2017
A2: Name of Employee | B2: ='Itinerary (3 copies)'!B2 -> WARREN A. DEL ROSARIO | C2: Emp No. | D2: 318
A3: Office | B3: Bureau of Soils and Water Management
A4: Division | B4: Agricultural Land Management and Evaluation Division
A5: Date | B5: Particulars | D5: Amount
A6: July 14, 2026 | B6: To Temporary Work Station, Tuguegarao City Tricycle | D6: ='Itinerary (3 copies)'!#REF! -> #REF!
B7: To Regulatory Division, DA-RFO 2, Tuguegarao City Tricycle | D7: ='Itinerary (3 copies)'!#REF! -> #REF!
A8: ='Itinerary (3 copies)'!#REF! -> #REF! | B8: ='Itinerary (3 copies)'!#REF! -> #REF! | D8: ='Itinerary (3 copies)'!#REF! -> #REF!
B15: Total | D15: =SUM(D6:D14) -> #REF!
A16: Purpose: To attend and participate in the 26th Scientific Conference and Annual Meeting of the Philippine Society of Soil Science and Technology Inc. (PSSST) with the theme, "Soil Intelegence for a Healthy Earth: Harnessing Data, AI and Innovation for Sustainable Soil Management,"
A18: I hereby certify that the above expenses are incurred as they are necessary for the above cited purpose, that above goods and services were acquired from parties not issuing receipts. And that I am fully aware that willful falsification of statement is punishable by law
B21: Certified Correct | C21: Noted By:
A22: Signature
A23: Printed Name | B23: ='Itinerary (3 copies)'!D17 -> WARREN A. DEL ROSARIO | C23: JOVETTE T. ALMEDA
B24: ='Itinerary (3 copies)'!D18 -> Agriculturist II | C24: Chief, ALMED
B25: Date: | C25: Date:

Sheet Fund Source
B2: Project | C2: Responsibility Center | D2: PREXC | E2: UACS Code | F2: Description
B3: STO-REG-ALMED | C3: 15-03-01-03 | D3: 200000-10000-1000 | E3: 5020101000-02 | F3: Travelling Expenses - Local
B4: STO-SEM-ALMED | C4: 15-03-04-03 | D4: 200000-10000-1000 | E4: 5020101000-02 | F4: Travelling Expenses - Local
B5: STO-FMHFWCROP-ALMED | C5: 15-03-01-03 | D5: 200000-120060-300 | E5: 5020101000-02 | F5: Travelling Expenses - Local
B6: LFPA-NSHP-ALMED | C6: 22-01-03-03 | D6: 330600-200030-3200 | E6: 5020101000-02 | F6: Travelling Expenses - Local
